<?xml version="1.0"?>
<robot name="two_wheel_car" xmlns:xacro="http://www.ros.org/wiki/xacro">

<material name="white">
    <color rgba="1 1 1 1"/>
</material>

<material name="orange">
    <color rgba="1 0.3 0.1 1"/>
</material>

<material name="blue">
    <color rgba="0.2 0.2 1 1"/>
</material>

<material name="black">
    <color rgba="0 0 0 1"/>
</material>

    <link name="base_footprint"/>

    <!-- Base Link -->
    <link name="base_link">
        <inertial>
            <mass value="5.0"/>
            <origin xyz="0 0 0" rpy="0 0 0"/>
            <inertia ixx="0.5" ixy="0.0" ixz="0.0" iyy="0.5" iyz="0.0" izz="0.5"/>
        </inertial>
        <visual>
            <origin xyz="0 0 0" rpy="0 0 0"/>
            <geometry>
                <box size="0.4 0.2 0.1"/>
            </geometry>
            <material name="orange"/>
        </visual>
        <collision>
            <origin xyz="0 0 0" rpy="0 0 0"/>
            <geometry>
                <box size="0.4 0.2 0.1"/>
            </geometry>
        </collision>
    </link>

    <joint name="base_joint" type="fixed">
        <origin xyz="0.0 0.0 0.05" rpy="0.0 0.0 0.0"/>
        <parent link="base_footprint"/>
        <child link="base_link"/>
    </joint>

    <!-- Left Wheel (now at the back) -->
    <link name="wheel_left">
        <inertial>
            <mass value="1.0"/>
            <origin xyz="0 0 0" rpy="0 0 0"/>
            <inertia ixx="0.1" ixy="0.0" ixz="0.0" iyy="0.1" iyz="0.0" izz="0.1"/>
        </inertial>
        <visual>
            <origin xyz="0 0 0" rpy="0 0 0"/>
            <geometry>
                <cylinder length="0.05" radius="0.05"/>
            </geometry>
            <material name="black"/>
        </visual>
        <collision>
            <origin xyz="0 0 0" rpy="0 0 0"/>
            <geometry>
                <cylinder length="0.05" radius="0.05"/>
            </geometry>
        </collision>
    </link>

    <!-- Right Wheel (now at the back) -->
    <link name="wheel_right">
        <inertial>
            <mass value="1.0"/>
            <origin xyz="0 0 0" rpy="0 0 0"/>
            <inertia ixx="0.1" ixy="0.0" ixz="0.0" iyy="0.1" iyz="0.0" izz="0.1"/>
        </inertial>
        <visual>
            <origin xyz="0 0 0" rpy="0 0 0"/>
            <geometry>
                <cylinder length="0.05" radius="0.05"/>
            </geometry>
            <material name="black"/>
        </visual>
        <collision>
            <origin xyz="0 0 0" rpy="0 0 0"/>
            <geometry>
                <cylinder length="0.05" radius="0.05"/>
            </geometry>
        </collision>
    </link>

    <!-- Caster Wheel Setup -->
    <!-- Caster Housing Link -->
    <link name="caster_housing">
        <inertial>
            <mass value="0.5"/>
            <origin xyz="0 0 0" rpy="0 0 0"/>
            <inertia ixx="0.001" ixy="0" ixz="0" iyy="0.001" iyz="0" izz="0.001"/>
        </inertial>
        <visual>
            <geometry>
                <cylinder radius="0.02" length="0.02"/>
            </geometry>
            <material name="blue"/>
        </visual>
        <collision>
            <geometry>
                <cylinder radius="0.02" length="0.02"/>
            </geometry>
        </collision>
    </link>

    <!-- Caster Wheel Link -->
    <link name="caster_wheel">
        <inertial>
            <mass value="0.3"/>
            <origin xyz="0 0 0" rpy="0 0 0"/>
            <inertia ixx="0.0001" ixy="0" ixz="0" iyy="0.0001" iyz="0" izz="0.0001"/>
        </inertial>
        <visual>
            <geometry>
                <sphere radius="0.03"/>
            </geometry>
            <material name="black"/>
        </visual>
        <collision>
            <geometry>
                <sphere radius="0.03"/>
            </geometry>
        </collision>
    </link>

    <link name="laser_frame">
        <visual>
            <geometry>
                <cylinder radius="0.08" length="0.05"/>
            </geometry>
            <material name="black"/>
        </visual>
        <collision>
            <geometry>
                <cylinder radius="0.08" length="0.05"/>
            </geometry>
        </collision>
        <inertial>
            <origin xyz="0 0 0.075" rpy="0 0 0"/>
            <mass value="0.1"/>
            <inertia ixx="0.0001808333333333333" ixy="0" ixz="0" iyy="0.0001808333333333333" iyz="0" izz="0.00032"/>
        </inertial>
    </link>

    <joint name="laser_joint" type="fixed">
        <parent link="base_link"/>
        <child link="laser_frame"/>
        <origin xyz="0 0 0.08" rpy="0 0 1.57"/>
    </joint>

    <gazebo reference="laser_frame">
        <material>Gazebo/Black</material>
        <sensor name="laser" type="ray">
            <pose> 0 0 0 0 0 0 </pose>
            <visualize>false</visualize>
            <update_rate>30</update_rate>
            <ray>
                <scan>
                    <horizontal>
                        <samples>360</samples>
                        <min_angle>-3.14</min_angle>
                        <max_angle>3.14</max_angle>
                    </horizontal>
                </scan>
                <range>
                    <min>0.3</min>
                    <max>12</max>
                </range>
            </ray>
            <plugin name="laser_controller" filename="libgazebo_ros_ray_sensor.so">
                <ros>
                    <remapping>~/out:=scan</remapping>
                </ros>
                <output_type>sensor_msgs/LaserScan</output_type>
                <frame_name>laser_frame</frame_name>
            </plugin>
        </sensor>
    </gazebo>

    <!-- Joints -->
    <joint name="left_wheel_joint" type="continuous">
        <parent link="base_link"/>
        <child link="wheel_left"/>
        <origin xyz="-0.15 0.13 -0.05" rpy="1.57 0 0"/>
        <axis xyz="0 0 1"/>
        <dynamics damping="0.1" friction="0.1"/>
    </joint>

    <joint name="right_wheel_joint" type="continuous">
        <parent link="base_link"/>
        <child link="wheel_right"/>
        <origin xyz="-0.15 -0.13 -0.05" rpy="1.57 0 0"/>
        <axis xyz="0 0 1"/>
        <dynamics damping="0.1" friction="0.1"/>
    </joint>

    <!-- Caster joints -->
    <!-- Housing joint to base_link (can rotate around z-axis) -->
    <joint name="caster_housing_joint" type="continuous">
        <parent link="base_link"/>
        <child link="caster_housing"/>
        <origin xyz="0.15 0 -0.05" rpy="0 0 0"/>
        <axis xyz="0 0 1"/>
    </joint>

    <!-- Wheel joint to housing (can rotate around y-axis) -->
    <joint name="caster_wheel_joint" type="continuous">
        <parent link="caster_housing"/>
        <child link="caster_wheel"/>
        <origin xyz="0 0 -0.03" rpy="0 0 0"/>
        <axis xyz="0 1 0"/>
    </joint>

    <!-- Gazebo-specific settings -->
    <gazebo reference="wheel_left">
        <mu1>0.9</mu1>
        <mu2>0.9</mu2>
        <material>Gazebo/Black</material>
    </gazebo>

    <gazebo reference="wheel_right">
        <mu1>0.9</mu1>
        <mu2>0.9</mu2>
        <material>Gazebo/Black</material>
    </gazebo>

    <gazebo reference="caster_wheel">
        <mu1>0.01</mu1>
        <mu2>0.01</mu2>
        <material>Gazebo/Black</material>
        <kp>1000000.0</kp>
        <kd>1.0</kd>
        <fdir1>1 0 0</fdir1>
    </gazebo>
    
    <gazebo>
        <plugin name="bot_joint_state" filename="libgazebo_ros_joint_state_publisher.so">
            <ros>
                <remapping>~/out:=joint_states</remapping>
            </ros>
            <update_rate>100</update_rate>
            <joint_name>left_wheel_joint</joint_name>
            <joint_name>right_wheel_joint</joint_name>
            <joint_name>caster_housing_joint</joint_name>
            <joint_name>caster_wheel_joint</joint_name>
        </plugin>
    </gazebo>

    <gazebo>
        <plugin name="differential_drive_controller" filename="libgazebo_ros_diff_drive.so">
            <!-- Wheel Information -->
            <update_rate>100</update_rate>
            <left_joint>left_wheel_joint</left_joint>
            <right_joint>right_wheel_joint</right_joint>
            <wheel_separation>0.26</wheel_separation>
            <wheel_diameter>0.1</wheel_diameter>

            <!-- Limits -->
            <max_wheel_torque>20.0</max_wheel_torque>
            <max_wheel_acceleration>1.0</max_wheel_acceleration>
            
            <!-- Output -->
            <command_topic>cmd_vel</command_topic>
            <publish_odom>true</publish_odom>
            <publish_odom_tf>true</publish_odom_tf>
            <odometry_frame>odom</odometry_frame>
            <robot_base_frame>base_footprint</robot_base_frame>
            <publish_wheel_tf>true</publish_wheel_tf>
        </plugin>
    </gazebo>

</robot>